Workbook

Sheet Toelichting
B1: Calculatiemodel Thebe 22 – VDL Bouw & Onderhoud B.V.
B2: Renovatie begane grond Thebe 22, Hilversum – meervoudig onderhandse aanbesteding, gunning op laagste prijs. Bedragen excl. BTW, prijspeil 2026.
B4: Doel
B5: Werkbegroting achter de officiële Inschrijfstaat (Bijlage 2). Het officiële formulier blijft ongewijzigd: het tabblad 'Inschrijfstaat' geeft per regel het bedrag dat u overneemt in de gele cel van het formulier (kolom 'Cel formulier').
B7: Hoe te gebruiken
B8: 1. Tabblad 'Begroting': vul hoeveelheden (kolom F) en eenheidsprijzen (kolom G) in. Blauwe tekst op geel = invoer. Zwarte tekst = formule.
B9: 2. Vervang elke 'Richtprijs' door de eigen norm of een offerte van een onderaannemer, en zet de status op 'Offerte ontvangen' of 'Eigen norm'.
B10: 3. Tabblad 'Risicos': kies per risico of u het meeprijst (Ja/Nee). Meegeprijsde risico's gaan als verwachte waarde (kans × impact) naar de genoemde post.
B11: 4. Tabblad 'Inschrijfstaat': vul de percentages AK, W&R en CAR in. Neem daarna de bedragen over in het formulier en controleer of het totaal gelijk is.
B12: 5. Tabblad 'Eenheidsprijzen': verrekenprijzen die E&W apart vraagt (isolatieherstel, snoeren). Die passen niet in het formulier: vraag de inkoper waar ze horen.
B13: 6. Tabblad 'Optimalisaties': optioneel deel onderaan het formulier (tellen niet mee in de gunning).
B15: BELANGRIJK – status van de bedragen
... B25: • BBN vraagt een open begroting, het formulier niet. Dien alleen het formulier in (de offerteaanvraag zegt: niet afwijken) en houd dit model klaar voor een eventueel verificatiegesprek.

Sheet Inschrijfstaat
A1: Over te nemen in Bijlage 2 – Inschrijfstaat Prijzenformulier (alleen de gele cellen van het formulier)
A3: Cel formulier | B3: Omschrijving | C3: % | D3: Begroting | E3: Risicos | F3: Bedrag in formulier | G3: Controle
B4: Installatietechnische werkzaamheden | F4: =SUM(F5:F13)
A5: E13 | B5: Ruimteverwarming en -koeling | D5: =SUMIFS(Begroting!$H$2:$H$111,Begroting!$A$2:$A$111,13) | E5: =SUMIFS(Risicos!$I$2:$I$17,Risicos!$H$2:$H$17,13) | F5: =ROUND(D5+E5,0) | G5: =IF(F5<=0,"FOUT: nul-bedrag niet toegestaan","ok")
A6: E14 | B6: Warmtapwaterinstallatie | D6: =SUMIFS(Begroting!$H$2:$H$111,Begroting!$A$2:$A$111,14) | E6: =SUMIFS(Risicos!$I$2:$I$17,Risicos!$H$2:$H$17,14) | F6: =ROUND(D6+E6,0) | G6: =IF(F6<=0,"FOUT: nul-bedrag niet toegestaan","ok")
A7: E15 | B7: Luchtbehandelingskast / ventilatie-installatie, incl. kanaalwerk | D7: =SUMIFS(Begroting!$H$2:$H$111,Begroting!$A$2:$A$111,15) | E7: =SUMIFS(Risicos!$I$2:$I$17,Risicos!$H$2:$H$17,15) | F7: =ROUND(D7+E7,0) | G7: =IF(F7<=0,"FOUT: nul-bedrag niet toegestaan","ok")
A8: E16 | B8: Verlichtingsinstallatie | D8: =SUMIFS(Begroting!$H$2:$H$111,Begroting!$A$2:$A$111,16) | E8: =SUMIFS(Risicos!$I$2:$I$17,Risicos!$H$2:$H$17,16) | F8: =ROUND(D8+E8,0) | G8: =IF(F8<=0,"FOUT: nul-bedrag niet toegestaan","ok")
A9: E17 | B9: Centrale elektrotechnische voorzieningen | D9: =SUMIFS(Begroting!$H$2:$H$111,Begroting!$A$2:$A$111,17) | E9: =SUMIFS(Risicos!$I$2:$I$17,Risicos!$H$2:$H$17,17) | F9: =ROUND(D9+E9,0) | G9: =IF(F9<=0,"FOUT: nul-bedrag niet toegestaan","ok")
A10: E18 | B10: Aanpassen regeltechniek | D10: =SUMIFS(Begroting!$H$2:$H$111,Begroting!$A$2:$A$111,18) | E10: =SUMIFS(Risicos!$I$2:$I$17,Risicos!$H$2:$H$17,18) | F10: =ROUND(D10+E10,0) | G10: =IF(F10<=0,"FOUT: nul-bedrag niet toegestaan","ok")
A11: E19 | B11: Communicatievoorzieningen | D11: =SUMIFS(Begroting!$H$2:$H$111,Begroting!$A$2:$A$111,19) | E11: =SUMIFS(Risicos!$I$2:$I$17,Risicos!$H$2:$H$17,19) | F11: =ROUND(D11+E11,0) | G11: =IF(F11<=0,"FOUT: nul-bedrag niet toegestaan","ok")
A12: E20 | B12: Toegangscontrole en beveiliging | D12: =SUMIFS(Begroting!$H$2:$H$111,Begroting!$A$2:$A$111,20) | E12: =SUMIFS(Risicos!$I$2:$I$17,Risicos!$H$2:$H$17,20) | F12: =ROUND(D12+E12,0) | G12: =IF(F12<=0,"FOUT: nul-bedrag niet toegestaan","ok")
A13: E21 | B13: Evt. andere bijkomende kosten (installaties) | D13: =SUMIFS(Begroting!$H$2:$H$111,Begroting!$A$2:$A$111,21) | E13: =SUMIFS(Risicos!$I$2:$I$17,Risicos!$H$2:$H$17,21) | F13: =ROUND(D13+E13,0) | G13: =IF(F13<=0,"FOUT: nul-bedrag niet toegestaan","ok")
B14: Bouwkundige voorzieningen | F14: =SUM(F15:F26)
A15: E23 | B15: Vervangen kozijnen, ramen en gevelpanelen/-onderdelen | D15: =SUMIFS(Begroting!$H$2:$H$111,Begroting!$A$2:$A$111,23) | E15: =SUMIFS(Risicos!$I$2:$I$17,Risicos!$H$2:$H$17,23) | F15: =ROUND(D15+E15,0) | G15: =IF(F15<=0,"FOUT: nul-bedrag niet toegestaan","ok")
A16: E24 | B16: Vervangen vloerafwerking en plinten | D16: =SUMIFS(Begroting!$H$2:$H$111,Begroting!$A$2:$A$111,24) | E16: =SUMIFS(Risicos!$I$2:$I$17,Risicos!$H$2:$H$17,24) | F16: =ROUND(D16+E16,0) | G16: =IF(F16<=0,"FOUT: nul-bedrag niet toegestaan","ok")
A17: E25 | B17: Aanpassen binnenwanden, -kozijnen en deuren | D17: =SUMIFS(Begroting!$H$2:$H$111,Begroting!$A$2:$A$111,25) | E17: =SUMIFS(Risicos!$I$2:$I$17,Risicos!$H$2:$H$17,25) | F17: =ROUND(D17+E17,0) | G17: =IF(F17<=0,"FOUT: nul-bedrag niet toegestaan","ok")
A18: E26 | B18: Vervangen plafondafwerking | D18: =SUMIFS(Begroting!$H$2:$H$111,Begroting!$A$2:$A$111,26) | E18: =SUMIFS(Risicos!$I$2:$I$17,Risicos!$H$2:$H$17,26) | F18: =ROUND(D18+E18,0) | G18: =IF(F18<=0,"FOUT: nul-bedrag niet toegestaan","ok")
A19: E27 | B19: Aanpassen zonwering | D19: =SUMIFS(Begroting!$H$2:$H$111,Begroting!$A$2:$A$111,27) | E19: =SUMIFS(Risicos!$I$2:$I$17,Risicos!$H$2:$H$17,27) | F19: =ROUND(D19+E19,0) | G19: =IF(F19<=0,"FOUT: nul-bedrag niet toegestaan","ok")
A20: E28 | B20: Realiseren vaste keukenvoorzieningen en pantry's | D20: =SUMIFS(Begroting!$H$2:$H$111,Begroting!$A$2:$A$111,28) | E20: =SUMIFS(Risicos!$I$2:$I$17,Risicos!$H$2:$H$17,28) | F20: =ROUND(D20+E20,0) | G20: =IF(F20<=0,"FOUT: nul-bedrag niet toegestaan","ok")
A21: E29 | B21: Realiseren douchevoorzieningen | D21: =SUMIFS(Begroting!$H$2:$H$111,Begroting!$A$2:$A$111,29) | E21: =SUMIFS(Risicos!$I$2:$I$17,Risicos!$H$2:$H$17,29) | F21: =ROUND(D21+E21,0) | G21: =IF(F21<=0,"FOUT: nul-bedrag niet toegestaan","ok")
A22: E30 | B22: Realiseren hekwerk terrein | D22: =SUMIFS(Begroting!$H$2:$H$111,Begroting!$A$2:$A$111,30) | E22: =SUMIFS(Risicos!$I$2:$I$17,Risicos!$H$2:$H$17,30) | F22: =ROUND(D22+E22,0) | G22: =IF(F22<=0,"FOUT: nul-bedrag niet toegestaan","ok")
A23: E31 | B23: Realiseren entree's, incl. bijbehorende voorzieningen | D23: =SUMIFS(Begroting!$H$2:$H$111,Begroting!$A$2:$A$111,31) | E23: =SUMIFS(Risicos!$I$2:$I$17,Risicos!$H$2:$H$17,31) | F23: =ROUND(D23+E23,0) | G23: =IF(F23<=0,"FOUT: nul-bedrag niet toegestaan","ok")
A24: E32 | B24: Realiseren fietsenstalling | D24: =SUMIFS(Begroting!$H$2:$H$111,Begroting!$A$2:$A$111,32) | E24: =SUMIFS(Risicos!$I$2:$I$17,Risicos!$H$2:$H$17,32) | F24: =ROUND(D24+E24,0) | G24: € 0 conform NvI vraag 3/29 (buiten beschouwing)
A25: E33 | B25: Doorvoeringen inbranden voor de installaties | D25: =SUMIFS(Begroting!$H$2:$H$111,Begroting!$A$2:$A$111,33) | E25: =SUMIFS(Risicos!$I$2:$I$17,Risicos!$H$2:$H$17,33) | F25: =ROUND(D25+E25,0) | G25: =IF(F25<=0,"FOUT: nul-bedrag niet toegestaan","ok")
A26: E34 | B26: Evt. andere bijkomende kosten (bouwkundig) | D26: =SUMIFS(Begroting!$H$2:$H$111,Begroting!$A$2:$A$111,34) | E26: =SUMIFS(Risicos!$I$2:$I$17,Risicos!$H$2:$H$17,34) | F26: =ROUND(D26+E26,0) | G26: =IF(F26<=0,"FOUT: nul-bedrag niet toegestaan","ok")
B27: Overige en bijkomende kosten | F27: =F28+F29+F30+F31+F32+F33
A28: E36 | B28: Engineering en coördinatiekosten | D28: =SUMIFS(Begroting!$H$2:$H$111,Begroting!$A$2:$A$111,36) | E28: =SUMIFS(Risicos!$I$2:$I$17,Risicos!$H$2:$H$17,36) | F28: =ROUND(D28+E28,0) | G28: =IF(F28<=0,"FOUT: nul-bedrag niet toegestaan","ok")
A29: E37 | B29: Revisietekeningen | D29: =SUMIFS(Begroting!$H$2:$H$111,Begroting!$A$2:$A$111,37) | E29: =SUMIFS(Risicos!$I$2:$I$17,Risicos!$H$2:$H$17,37) | F29: =ROUND(D29+E29,0) | G29: =IF(F29<=0,"FOUT: nul-bedrag niet toegestaan","ok")
A30: E38 | B30: Algemene Bouwplaatskosten (ABK) | D30: =SUMIFS(Begroting!$H$2:$H$111,Begroting!$A$2:$A$111,38) | E30: =SUMIFS(Risicos!$I$2:$I$17,Risicos!$H$2:$H$17,38) | F30: =ROUND(D30+E30,0) | G30: =IF(F30<=0,"FOUT: nul-bedrag niet toegestaan","ok")
A31: E39 / D39 | B31: Algemene Kosten (AK) – % over directe kosten incl. ABK | C31: 0.07 | F31: =ROUND(C31*(F4+F14+F28+F29+F30),0) | G31: =IF(F31<=0,"FOUT: nul-bedrag niet toegestaan","ok")
A32: E40 / D40 | B32: Winst en Risico (W&R) – % over directe kosten + AK | C32: 0.03 | F32: =ROUND(C32*((F4+F14+F28+F29+F30)+F31),0) | G32: =IF(F32<=0,"FOUT: nul-bedrag niet toegestaan","ok")
A33: E41 / D41 | B33: CAR – % over directe kosten + AK + W&R | C33: 0.0025 | F33: =ROUND(C33*((F4+F14+F28+F29+F30)+F31+F32),0) | G33: =IF(F33<=0,"FOUT: nul-bedrag niet toegestaan","ok")
B35: Totaal exclusief BTW (= inschrijfbedrag, cel E43 formulier) | F35: =F4+F14+F27
B36: Controle: aantal regels met nul-bedrag | F36: =COUNTIF(G4:G33,"FOUT*")
B38: Kengetallen ter controle
B39: Verbouwd vloeroppervlak BG (m²) – E&W 4.1.1 | C39: 1290
B40: Aantal slaapkamers / eenheden – BBN 2.1 | C40: 29
B41: Inschrijfbedrag per m² verbouwd | F41: =F35/C39
B42: Inschrijfbedrag per eenheid | F42: =F35/C40
B43: Aandeel installaties in directe kosten | F43: =F4/(F4+F14+F28+F29+F30)
...

Sheet Begroting
A1: Post | B1: Inschrijfstaat-regel | C1: Omschrijving | D1: Bron (§) | E1: Eenh. | F1: Hoeveelheid | G1: Eenheidsprijs | H1: Bedrag | I1: Uitvoering | J1: Status prijs | K1: Opmerking / aandachtspunt
A2: 13 | B2: Ruimteverwarming en -koeling | C2: Nieuwe ventilatorconvector CIAT Major MAJ2 430, incl. 4 aftakkingen hoofdtracé, drukgecomp. regelafsluiter, afsluiters, Raminex-flex, isolatie | D2: E&W 7.1/7.4.2 | E2: st | F2: 5 | G2: 4200 | H2: =F2*G2 | I2: OA W-installateur | J2: Richtprijs | K2: Telling L.0.01-A/B: 34 fancoils nodig (29 kamers + 3 keuken 0.24 + 1 keuken 0.64 + 1 personeelsruimte 0.73); D.0.01-A/B toont 29 bestaande → 5 nieuw. Bouwgrootte: grootste aanhouden (E&W 7.4.2)
A3: 13 | B3: Ruimteverwarming en -koeling | C3: Bestaande ventilatorconvector demonteren en in zelfde ruimte terugplaatsen, incl. nieuwe regel-/inregelafsluiters | D3: E&W 5.7/7.1 | E3: st | F3: 29 | G3: 1400 | H3: =F3*G3 | I3: OA W-installateur | J3: Richtprijs | K3: 29 bestaande fancoils volgens demontagetekeningen D.0.01-A (19) en D.0.01-B (10)
A4: 13 | B4: Ruimteverwarming en -koeling | C4: Kanaalverwarmer/-koeler 4-pijps (ruimten 0.04, 0.05, 0.44, 0.45, 0.62, 0.63) | D4: E&W 7.1 | E4: st | F4: 6 | G4: 2800 | H4: =F4*G4 | I4: OA W-installateur | J4: Richtprijs | K4: 7.1 noemt 6 ruimten, 7.4.2 noemt er 5 (0.63 ontbreekt) – 6 aangehouden
A5: 13 | B5: Ruimteverwarming en -koeling | C5: Ruimtethermostaat CIAT incl. inbouw in brandwerende wand | D5: E&W 9.2.3 / Componentenboek nr. 24 | E5: st | F5: 40 | G5: 190 | H5: =F5*G5 | I5: OA W-installateur | J5: Richtprijs | K5: Type-conflict: E&W 99DAsei, componentenboek RTR-E 7203. Gelijk aan verdiepingen aanhouden
A6: 13 | B6: Ruimteverwarming en -koeling | C6: Vloerverwarming: IR-scan, revisietekening, groepen douchezones dichtzetten, PvA | D6: E&W 7.3 / BBN 3.2.1 | E6: post | F6: 1 | G6: 6500 | H6: =F6*G6 | I6: OA W-installateur | J6: Richtprijs | K6: PvA vloerverwarming is verplicht onderdeel van de aanbieding!
A7: 13 | B7: Ruimteverwarming en -koeling | C7: Waterzijdig inregelen CV/GKW BG + rapport met debiet per bouwlaag (Delta-P) | D7: E&W 4.2.2/7.5 | E7: post | F7: 1 | G7: 7500 | H7: =F7*G7 | I7: Delta-P (voorgeschreven) | J7: Offerte aanvragen | K7: Delta-P is voorgeschreven: offerte opvragen
A8: 13 | B8: Ruimteverwarming en -koeling | C8: Condensafvoeren ventilatorconvectoren met sifon op VWA-stelsel | D8: E&W 6.1.1 | E8: st | F8: 40 | G8: 220 | H8: =F8*G8 | I8: OA W-installateur | J8: Richtprijs | K8: 34 fancoils + 6 kanaalverwarmers
A9: 14 | B9: Warmtapwaterinstallatie | C9: Nieuwe deelring warmtapwater-circulatie BG + koudwaterstelsel boven plafond (koper, pers), afsluiters per strang, isolatie | D9: E&W 6.2.4 | E9: post | F9: 1 | G9: 19500 | H9: =F9*G9 | I9: OA W-installateur | J9: Richtprijs | K9: Aftakken vanaf schacht noord/midden/zuid; MMV-tapwaterberekening
A10: 14 | B10: Warmtapwaterinstallatie | C10: Douche-aansluiting warm/koud incl. afvoer en RVS-afvoerput Aquaberg 4815 (0.37, 0.42, 0.70, 0.71) | D10: E&W 6.1/6.2 + T.0.01 + Componentenboek nr. 6 | E10: st | F10: 10 | G10: 1600 | H10: =F10*G10 | I10: OA W-installateur | J10: Richtprijs | K10: T.0.01: 4 douches 0.42 + 4 douches 0.37 + 2 (0.70/0.71). 0.37 staat niet in de E&W-tekst
A11: 14 | B11: Warmtapwaterinstallatie | C11: De Melker M-Check douchepaneel MC.501229 (thermostaat, piëzo, tijdsbegrenzing, spoelfunctie) per douche | D11: E&W 6.2.1/9.3 + Componentenboek nr. 4 | E11: st | F11: 10 | G11: 1450 | H11: =F11*G11 | I11: OA W-installateur | J11: Offerte aanvragen | K11: Voorgeschreven fabricaat; 10 douches volgens T.0.01
A12: 14 | B12: Warmtapwaterinstallatie | C12: M-Check centrale regelmodule / samenvoeging zones | D12: E&W 9.3.3 | E12: st | F12: 1 | G12: 2500 | H12: =F12*G12 | I12: OA W-installateur | J12: Offerte aanvragen
A13: 14 | B13: Warmtapwaterinstallatie | C13: Wastrog Intersan Sanilav 3.0 RVS 1200 mm incl. kranen en aansluiting (0.37 en 0.42) | D13: Componentenboek nr. 5 + T.0.01 | E13: st | F13: 4 | G13: 2100 | H13: =F13*G13 | I13: OA W-installateur | J13: Offerte aanvragen | K13: T.0.01: 8 tappunten → 4 wastroggen van 2 tappunten (aanname); fabricaat volgens componentenboek
A14: 14 | B14: Warmtapwaterinstallatie | C14: MIVA-toiletruimte 0.72: wandcloset Geberit 300 comfort verlengd + Duofix + Linido steunen, MIVA-wastafel Geberit 300 comfort + Hansgrohe Care | D14: Componentenboek nr. 9/11 + T.0.01 (WC-02/WT-02) | E14: post | F14: 1 | G14: 2900 | H14: =F14*G14 | I14: OA W-installateur | J14: Offerte aanvragen | K14: WC-02/WT-02 op T.0.01; uitvoering volgens componentenboek
A15: 14 | B15: Warmtapwaterinstallatie | C15: Aansluiten tappunten aanrechten 0.24 (3), 0.64 (3) en pantry 0.01 (1) (warm/koud + afvoer; 0.24 via nieuw tracé naar vetafscheider) | D15: E&W 6.1.1 + T.0.01 | E15: st | F15: 7 | G15: 950 | H15: =F15*G15 | I15: OA W-installateur | J15: Richtprijs
A16: 14 | B16: Warmtapwaterinstallatie | C16: Wasmachine-aansluitingen 0.57 incl. nieuwe afvoer (boren i.c.m. vloerverwarming) | D16: E&W 6.1.1 | E16: st | F16: 4 | G16: 1150 | H16: =F16*G16 | I16: OA W-installateur | J16: Richtprijs | K16: Aantal wasmachines uittellen
A17: 14 | B17: Warmtapwaterinstallatie | C17: 2 standaard wandclosets 0.66/0.67 (vervangen kinderclosets, aansluitingen hergebruiken) + demonteren/afdoppen kinderclosets 0.70/0.71 | D17: E&W 5.4/5.5 + NvI vraag 30 | E17: post | F17: 1 | G17: 4000 | H17: =F17*G17 | I17: OA W-installateur | J17: Richtprijs | K17: NvI vraag 30: het nieuwe sanitair betreft 2 standaard wandclosets
A18: 14 | B18: Warmtapwaterinstallatie | C18: Uitbreiding VWA-stelsel: ca. 40 m PVC in plafond parkeergarage (R.-1.01) + ca. 12 vloerdoorboringen, Dyka Sono in plafonds, brandmanchetten | D18: E&W 6.1.3 + R.-1.01/R.0.01 | E18: post | F18: 1 | G18: 16000 | H18: =F18*G18 | I18: OA W-installateur | J18: Richtprijs | K18: R.-1.01: nieuwe leiding in kelder naar vetafscheider. Kernboringen door BG-vloer met vloerverwarming
A19: 14 | B19: Warmtapwaterinstallatie | C19: Afpersen, spoelen, legionellabemonstering + vrijverklaring | D19: E&W 6.2.5 | E19: post | F19: 1 | G19: 1500 | H19: =F19*G19 | I19: OA W-installateur | J19: Richtprijs
A20: 15 | B20: Luchtbehandelingskast / ventilatie-installatie, incl. kanaalwerk | C20: Demontage kanalen, roosters en appendages BG conform demontagetekeningen, afplakken kanaalsysteem | D20: E&W 5.8 | E20: post | F20: 1 | G20: 6500 | H20: =F20*G20 | I20: OA W-installateur | J20: Richtprijs
A21: 15 | B21: Luchtbehandelingskast / ventilatie-installatie, incl. kanaalwerk | C21: Nieuw kanalenstelsel verzinkt klasse C vanaf schachtuittrede, per ruimte (toevoer + retour/overstroom), incl. isolatie toevoer | D21: E&W 8.1/8.4.5/8.7 | E21: ruimte | F21: 40 | G21: 1350 | H21: =F21*G21 | I21: OA W-installateur | J21: Richtprijs | K21: L.0.01-A/B: 29 kamers + keukens, personeelsruimte, gespreksruimten, badruimten
A22: 15 | B22: Luchtbehandelingskast / ventilatie-installatie, incl. kanaalwerk | C22: Brandklep Solid Air FDC motorbediend 24V veerteruggang (toevoer + retour per kamerwand) | D22: E&W 8.4.2/9.4 | E22: st | F22: 64 | G22: 780 | H22: =F22*G22 | I22: OA W-installateur | J22: Offerte aanvragen | K22: L.0.01 + E.001: 2 per kamer = 58, plus ca. 6 in 60-min scheidingen. Componentenboek nr. 21: FDC25 24V DC (typeconflict E&W opgelost)
A23: 15 | B23: Luchtbehandelingskast / ventilatie-installatie, incl. kanaalwerk | C23: Roosters Solid Air (CTV/CRVM/RTB/RRB) incl. ≥1 m akoestische slang en instelklep | D23: E&W 8.4.3 | E23: st | F23: 230 | G23: 175 | H23: =F23*G23 | I23: OA W-installateur | J23: Richtprijs | K23: L.0.01: per kamer 6 roosters (CTV, CRVM, 2× RTB, 2× RRB) = 174 + ca. 56 in keukens/overige ruimten
A24: 15 | B24: Luchtbehandelingskast / ventilatie-installatie, incl. kanaalwerk | C24: Verlaagde plenumbox Solid Air model 450 per fancoil (toevoer + recirculatie) | D24: Componentenboek nr. 17 | E24: st | F24: 34 | G24: 260 | H24: =F24*G24 | I24: OA W-installateur | J24: Richtprijs | K24: Gelijk aan verdiepingen
A25: 15 | B25: Luchtbehandelingskast / ventilatie-installatie, incl. kanaalwerk | C25: Plenumafzuiging gang + geluiddempende deurroosters (2 st) | D25: E&W 8.4.1 | E25: post | F25: 1 | G25: 4500 | H25: =F25*G25 | I25: OA W-installateur | J25: Richtprijs
A26: 15 | B26: Luchtbehandelingskast / ventilatie-installatie, incl. kanaalwerk | C26: Boxventilator wasruimte 0.57 met vochtregeling en tijdklok | D26: E&W 8.5 | E26: st | F26: 1 | G26: 2600 | H26: =F26*G26 | I26: OA W-installateur | J26: Richtprijs
A27: 15 | B27: Luchtbehandelingskast / ventilatie-installatie, incl. kanaalwerk | C27: Recirculatie-afzuigkap Quattro Correto CW4090 + plasmafilter (4 st keuken 0.24, 4 st keuken 0.64) | D27: E&W 8.4.6/8.4.7 | E27: st | F27: 8 | G27: 4600 | H27: =F27*G27 | I27: Techno Horeca / OA | J27: Offerte aanvragen | K27: Offerte Techno Horeca is bijgevoegd – bedrag overnemen. E.001 toont 7 AK-aansluitpunten, E&W 8 kappen; BBN 3.7.2 noemt wasemschouw + wandkappen
A28: 15 | B28: Luchtbehandelingskast / ventilatie-installatie, incl. kanaalwerk | C28: Luchtzijdig inregelen gehele BG + één gecombineerd meetrapport (Delta-P) | D28: E&W 8.6 | E28: post | F28: 1 | G28: 5000 | H28: =F28*G28 | I28: Delta-P (voorgeschreven) | J28: Offerte aanvragen
A29: 16 | B29: Verlichtingsinstallatie | C29: Verlichtingsarmaturen LED (downlights, inleg 600x600, plafonnière + hanglamp kamers) incl. aansluiting | D29: E&W 10.9 | E29: st | F29: 215 | G29: 210 | H29: =F29*G29 | I29: OA E-installateur | J29: Richtprijs | K29: E.001: A1 60x60 (92), E1/E2 downlights (36), F (8), W (9), H hanglamp (1 per kamer); typische kamers doorgerekend naar 29
A30: 16 | B30: Verlichtingsinstallatie | C30: Noodverlichting en vluchtwegsignalering decentraal (autonoom) | D30: E&W 10.10 + E.001 | E30: st | F30: 25 | G30: 265 | H30: =F30*G30 | I30: OA E-installateur | J30: Richtprijs | K30: E.001: 11 NV/NV1-punten getekend + pictogrammen; aantal volgt uit projectering NEN 1838
A31: 16 | B31: Verlichtingsinstallatie | C31: Aanwezigheidsdetectie / DALI-dimmers / nachtbedrijf gangen en sanitair | D31: E&W 10.11 | E31: st | F31: 25 | G31: 160 | H31: =F31*G31 | I31: OA E-installateur | J31: Richtprijs
A32: 17 | B32: Centrale elektrotechnische voorzieningen | C32: Nieuwe verdeelinrichting keuken (LKK) incl. voedingskabel vanuit HSVI parkeergarage | D32: E&W 10.6 | E32: st | F32: 1 | G32: 9500 | H32: =F32*G32 | I32: OA E-installateur | J32: Richtprijs | K32: Kabellengte parkeergarage → keuken bepalen
A33: 17 | B33: Centrale elektrotechnische voorzieningen | C33: Aanpassen LK0-1 en LK0-2 (groepen, 20% reserve) incl. overspanningsbeveiliging + signaleringslamp | D33: E&W 10.6.1/10.8 | E33: st | F33: 2 | G33: 3800 | H33: =F33*G33 | I33: OA E-installateur | J33: Richtprijs
A34: 17 | B34: Centrale elektrotechnische voorzieningen | C34: Wandcontactdozen / aansluitpunten incl. leidingwerk in buis | D34: E&W 10.7 | E34: st | F34: 95 | G34: 135 | H34: =F34*G34 | I34: OA E-installateur | J34: Richtprijs | K34: E.001: KK per kamer + keukens (~32), 3O per kamer (29), Alg. (14), WM (4), DR (3), overig. Let op: punten die niet op tekening staan, horen er ook bij (10.7)
A35: 17 | B35: Centrale elektrotechnische voorzieningen | C35: Krachtaansluitingen inductiekookplaten (6 st) en afzuigkappen | D35: E&W 10.7.6 | E35: st | F35: 14 | G35: 420 | H35: =F35*G35 | I35: OA E-installateur | J35: Richtprijs
A36: 17 | B36: Centrale elektrotechnische voorzieningen | C36: Voedingen ventilatorconvectoren, brandkleppen, M-Check, boxventilator | D36: E&W 9.2.1/9.4.1 | E36: st | F36: 45 | G36: 175 | H36: =F36*G36 | I36: OA E-installateur | J36: Richtprijs
A37: 17 | B37: Centrale elektrotechnische voorzieningen | C37: Aarding en potentiaalvereffening (incl. natte ruimten) | D37: E&W 10.4 | E37: post | F37: 1 | G37: 3200 | H37: =F37*G37 | I37: OA E-installateur | J37: Richtprijs
A38: 17 | B38: Centrale elektrotechnische voorzieningen | C38: Kabelgoten / kanalisatie + 35 m nieuw wandgootdeksel | D38: E&W 10.5 | E38: post | F38: 1 | G38: 6200 | H38: =F38*G38 | I38: OA E-installateur | J38: Richtprijs
A39: 17 | B39: Centrale elektrotechnische voorzieningen | C39: NEN 3140 / NEN 1010 metingen en rapportage | D39: E&W 3.9.3 | E39: post | F39: 1 | G39: 1600 | H39: =F39*G39 | I39: OA E-installateur | J39: Richtprijs
A40: 18 | B40: Aanpassen regeltechniek | C40: Demonteren vervallen I/O-punten, GBS-datapunten en bekabeling, opschonen regelkasten (Priva ongewijzigd) | D40: E&W 5.9 | E40: post | F40: 1 | G40: 3500 | H40: =F40*G40 | I40: OA W/regeltechniek | J40: Richtprijs | K40: Geen nul-prijs: deze post heeft wel inhoud
...

Sheet Risicos
A1: Nr | B1: Risico | C1: Bron (§) | D1: Kans | E1: Impact (€) | F1: Verwachte waarde | G1: Meeprijzen? (Ja/Nee) | H1: Naar post | I1: Opgenomen bedrag | J1: Toelichting / beheersmaatregel
A2: 1 | B2: Schade aan vloerverwarming bij boren/bevestigen (geen revisie beschikbaar) | C2: BBN 3.2.1 / E&W 7.3 | D2: 0.3 | E2: 8000 | F2: =D2*E2 | G2: Ja | H2: 13 | I2: =IF(G2="Ja",F2,0) | J2: Valt onder garantie opdrachtnemer. IR-scan vooraf, boorlocaties markeren.
A3: 2 | B3: Meer kapotte ruiten of kozijnvervanging dan aangenomen (25 m²) | C3: BBN 3.1.3 | D3: 0.5 | E3: 6000 | F3: =D3*E3 | G3: Ja | H3: 23 | I3: =IF(G3="Ja",F3,0) | J3: Scope stelt u zelf vast bij opname. Schouw vóór inschrijving, anders aanname expliciet maken.
A4: 3 | B4: Wanden tot betondek met extra brandmanchetten rond bestaande leidingen boven de kamers | C4: BBN 3.3.1 / E&W 7.1 | D4: 0.4 | E4: 15000 | F4: =D4*E4 | G4: Ja | H4: 25 | I4: =IF(G4="Ja",F4,0) | J4: Bestaande leidingen lopen over de kamers en moeten in de 'drukschotten' worden opgenomen.
A5: 4 | B5: Capaciteit bestaande BMC onvoldoende (extra lus/paneel) | C5: E&W 12.2.3 | D5: 0.3 | E5: 6000 | F5: =D5*E5 | G5: Ja | H5: 20 | I5: =IF(G5="Ja",F5,0) | J5: Capaciteit vooraf laten checken door de onderhoudspartij BMI.
A6: 5 | B6: Ondergrond vloer vraagt zwaarder herstel dan egaliseren | C6: BBN 3.2.1 | D6: 0.4 | E6: 6000 | F6: =D6*E6 | G6: Ja | H6: 24 | I6: =IF(G6="Ja",F6,0)
A7: 6 | B7: Legionella: positieve monsters, spoelen/desinfectie, herbemonstering | C7: E&W 6.2.5 | D7: 0.2 | E7: 2500 | F7: =D7*E7 | G7: Ja | H7: 14 | I7: =IF(G7="Ja",F7,0) | J7: Kosten volledig voor de aannemer.
A8: 7 | B8: Productiviteitsverlies in bewoond gebouw (08–16 uur; afbouw ±1 uur ruimer toegestaan) | C8: E&W 3.2 + NvI vraag 15 | D8: 0.4 | E8: 5000 | F8: =D8*E8 | G8: Ja | H8: 38 | I8: =IF(G8="Ja",F8,0)
A9: 8 | B9: Versnelling / uitloop: start ca. 9 nov, oplevering eind 2026 met max. 6 weken uitloop (NvI vraag 8/28) | C9: Offerteaanvraag + NvI vraag 8/28 | D9: 0.4 | E9: 10000 | F9: =D9*E9 | G9: Ja | H9: 38 | I9: =IF(G9="Ja",F9,0) | J9: Overwerk mag alleen met schriftelijke toestemming. Beter: realistische planning met benoemde afhankelijkheden.
A10: 9 | B10: Pantry's slaapkamers met water: close-in boiler, sifon en aansluitingen zoals op de verdiepingen (29 kamers) | C10: BBN 3.7.3 + Componentenboek nr. 1–3 vs E&W 6.1/6.2 + T.0.01 | D10: 0.4 | E10: 45000 | F10: =D10*E10 | G10: Nee | H10: 14 | I10: =IF(G10="Ja",F10,0) | J10: Componentenboek (verdiepingen 2022) heeft per kamer een Inventum Q10 close-in boiler + sifon; E&W en T.0.01/R.0.01 tonen voor de BG geen water naar de kamers. Niet meegeprijsd.
A11: 10 | B11: Constant-volumeregelaars Solid Air VCMHAR per kamer zoals op verdiepingen | C11: Componentenboek nr. 14 vs L.0.01 | D11: 0.2 | E11: 9000 | F11: =D11*E11 | G11: Nee | H11: 15 | I11: =IF(G11="Ja",F11,0) | J11: Niet in E&W/L.0.01 (handbediende inregelkleppen). Niet meegeprijsd.
A12: 11 | B12: Kernboringen door BG-vloer boven parkeergarage: vloerverwarming en brandwerend dichten | C12: R.-1.01 / E&W 6.1.1 | D12: 0.3 | E12: 4000 | F12: =D12*E12 | G12: Ja | H12: 14 | I12: =IF(G12="Ja",F12,0) | J12: Ca. 12 doorboringen; garage is apart brandcompartiment.
A13: 12 | B13: Werk op 1e en 2e verdieping volgens Bijlage 1 (DO-11): 3 personeelstoiletten 1e verd. incl. W/E; herplaatsen glaswand + deuren, OSB-passtukken en voorzetwand 2e verd. | C13: Bijlage 1 blad 3 + NvI vraag 21 | D13: 0.6 | E13: 24500 | F13: =D13*E13 | G13: Ja | H13: 34 | I13: =IF(G13="Ja",F13,0) | J13: Staat niet in BBN/E&W, maar wel in de bijlage die integraal onderdeel is. NvI 21: glazen wanden hergebruiken op deze locatie.
A14: 13 | B14: Terreininrichting volgens Bijlage 1: taxushaag in plantenbakken (2,3 m), ACP-scheidingswanden, verplaatsen plantenbakken, zeecontainer als rookruimte; sportveld n.t.b. | C14: Bijlage 1 blad 1 | D14: 0.3 | E14: 45000 | F14: =D14*E14 | G14: Nee | H14: 34 | I14: =IF(G14="Ja",F14,0) | J14: Niet in BBN 3.8 (alleen entrees, hekwerk, fietsenstalling). Niet meegeprijsd; sportveld expliciet n.t.b.
A15: 14 | B15: Twee versies plattegrond: Bijlage 1/3 (DO-01, 13-02) wijkt af van Bijlage 4 en installatietekeningen (BV-11, 28-04) | C15: Bijlage 1/3 vs 4 | D15: 0.3 | E15: 8000 | F15: =D15*E15 | G15: Ja | H15: 25 | I15: =IF(G15="Ja",F15,0) | J15: O.a. 0.64 (52 vs 33 m²), 0.44/0.45 douches vs gespreksruimten, 0.47. BBN noemt Bijlage 1 leidend voor te handhaven/slopen wanden. Prijs op BV-11.
A16: 15 | B16: Tellingen uit PDF-tekeningen wijken af van de werkelijke aantallen | C16: Tekeningen E.001, L.0.01, T.0.01 | D16: 0.3 | E16: 10000 | F16: =D16*E16 | G16: Ja | H16: 36 | I16: =IF(G16="Ja",F16,0) | J16: Tellingen zijn visueel/uit tekstlabels. Laat installateurs natellen op DWG (NvI vraag 2).
A17: 16 | B17: WKO-capaciteit / inregelen onvoldoende (nooit waterzijdig ingeregeld) | C17: E&W 4.2.2/7.1 | D17: 0.15 | E17: 8000 | F17: =D17*E17 | G17: Nee | H17: 13 | I17: =IF(G17="Ja",F17,0) | J17: Het bestek stelt dat de aannemer mag uitgaan van voldoende capaciteit, dus dit risico ligt bij de opdrachtgever.
B19: Totaal meegeprijsde risico's | I19: =SUM(I2:I17)
B20: Totaal verwachte waarde alle risico's (ter info) | I20: =SUM(F2:F17)

Sheet Eenheidsprijzen
A1: Verrekenprijzen die E&W apart vraagt (niet in het formulier)
A3: Omschrijving | B3: Eenh. | C3: Prijs | D3: Status | E3: Bron
A4: Herstel isolatie CV-leiding, steenwol 30 mm + alufolie, t/m DN25 | B4: m1 | C4: 28 | D4: Richtprijs | E4: E&W 5.2 – meerwerk op basis van meterprijs
A5: Herstel isolatie CV-leiding, steenwol 30 mm + alufolie, DN32–DN50 | B5: m1 | C5: 38 | D5: Richtprijs | E5: E&W 5.2
A6: Herstel isolatie GKW-leiding Armaflex AF-13/AF-19, t/m DN25 | B6: m1 | C6: 32 | D6: Richtprijs | E6: E&W 5.2
A7: Herstel isolatie GKW-leiding Armaflex AF-19, DN32–DN50 | B7: m1 | C7: 44 | D7: Richtprijs | E7: E&W 5.2
A8: Aansluitsnoer RJ-45 CAT6a afwijkende lengte (3,0 m) | B8: st | C8: 9 | D8: Richtprijs | E8: E&W 11.2.1
A9: Aansluitsnoer RJ-45 CAT6a afwijkende lengte (5,0 m) | B9: st | C9: 12 | D9: Richtprijs | E9: E&W 11.2.1
A10: Patchsnoer RJ-45 CAT6a afwijkende kleur/lengte | B10: st | C10: 8 | D10: Richtprijs | E10: E&W 11.2.1

Sheet Optimalisaties
B1: Optimalisaties (optioneel, formulierregels 49–51) – tellen niet mee in de gunning
A3: # | B3: Omschrijving (voordeel t.o.v. basis) | C3: Indicatie meer/minder | D3: Toelichting / voorwaarde
A4: 1 | B4: Prefab/gestandaardiseerde pantry-units voor alle slaapkamers (één type) | C4: -6000 | D4: Minder montage-uren en kortere levertijd. Past binnen HPL/RVS-eisen BBN 3.7.3.
A5: 2 | B5: Alternatief fabricaat recirculatie-afzuigkappen (aantoonbaar gelijkwaardig) | C5: -5000 | D5: Toegestaan volgens E&W 8.4.6/8.4.7. Gelijkwaardigheid onderbouwen.
A6: 3 | B6: Planningsvoorstel: gefaseerde oplevering (eerst zuidvleugel, dan noord) | C6: 0 | D6: Geen kostenverschil, wel eerder bewoonbaar en minder planningsrisico.

Sheet NvI
A1: Nota van Inlichtingen TN-606498 (21-09-2026) – antwoorden en verwerking in het model
A2: Bron: NvI met antwoorden (14 pagina's, vragen 3–17 en 19–30). Vraag 1 verwijst naar het componentenboek (zie tabblad Componentenboek). Vraag 2 (DWG) en vraag 18 staan niet in het ontvangen document.
A4: # | B4: Vraag (samengevat) | C4: Antwoord opdrachtgever | D4: Verwerking in model
A5: 1 | B5: Materiaalboek SPIE / sanitairboek ontbreekt | C5: Componentenboek toegevoegd | D5: Fabricaten verwerkt, zie tabblad Componentenboek.
A6: 2 | B6: DWG-bestanden? | C6: Niet in ontvangen document | D6: Tellingen blijven uit PDF; risicopost € 10.000 gehandhaafd.
A7: 3 | B7: Afprijzen lichtplan, warmteverlies, fietsenstalling | C7: Lichtplan en warmteverliesberekening horen bij de engineering. Fietsenstalling buiten beschouwing. | D7: E32 = € 0; engineering in E36 ongewijzigd.
A8: 4 | B8: Stoot-/inbraakwerendheid wanden | C8: Hotelstandaard; geen extra inbraakwerendheid wanden; nieuw hang- en sluitwerk SKG2. | D8: Sluitwerk verhoogd naar € 150/st (SKG2).
A9: 5 | B9: 59 dB: DnT,A of Rw? | C9: Alleen bij kantoor- en overlegplekken, zoals omschreven. | D9: Dubbele frame wand alleen 0.04/0.05/0.62/0.63 (60 m²) – ongewijzigd.
A10: 6 | B10: Alle kamerscheidende wanden volledig nieuw? | C10: Ja, opdrachtgever is zich hiervan bewust. | D10: 300 m1 nieuwe wand tot betondek – ongewijzigd.
A11: 7 | B11: Brandklasse gordijnen en tapijt | C11: Wat gebruikelijk is voor hotelfunctie. | D11: Gordijnen brandvertragend: € 110/m1.
A12: 8 | B12: Planning krap, V&G 4 weken vooraf | C12: V&G-plan 2 weken vooraf in concept. Uitloop maximaal 6 weken. | D12: Versnellingsrisico verlaagd (40% × € 10.000); uitvoerder 13 weken.
A13: 9 | B13: Parkeren | C13: Geen plekken op terrein; openbare weg is betaald parkeren. | D13: Parkeerkosten € 2.600 in ABK.
A14: 10 | B14: Type plafond | C14: 60x60 witte tegels. | D14: Ongewijzigd.
A15: 11 | B15: Tapijt + marmoleum combineren? | C15: Al het tapijt eruit; alle ruimten naadloze marmoleum-achtige afwerking. | D15: Tapijttegels vervallen; marmoleum 1.050 m².
A16: 12 | B16: RVS-keukenkasten i.p.v. HPL? | C16: Uitgaan van de vraagspecificatie (HPL). | D16: Ongewijzigd; optimalisatie vervallen.
... A33: 30 | B33: Omschrijving nieuw sanitair | C33: 2 standaard wandclosets. | D33: Post closets 0.66/0.67 aangepast naar € 4.000.
A35: Let op: de NvI noemt Gemeente Wijdemeren als aanbestedende dienst en is gedateerd na de oorspronkelijke sluitingsdatum (18-09). Controleer de actuele sluitingsdatum op TenderNed.

Sheet Componentenboek
A1: Componentenboek W-installaties HILV-THEBE22-SPEC-001 rev. 1.0 (SPIE, 12-07-2022) – toepassing op de begane grond
A2: Opgesteld voor de verbouwing van de verdiepingen (2022). Volgens E&W 3.6 gelden deze fabricaten ook voor de BG, tenzij de werkomschrijving anders voorschrijft.
A4: Nr | B4: Component | C4: Fabricaat / type | D4: Post | E4: Verwerking
A5: 1 | B5: Keukenmengkraan keukenblokjes kamer | C5: Levering bouwkundige aannemer | D5: E28 | E5: Alleen relevant als pantry's water krijgen – zie risico.
A6: 2 | B6: Close-in boiler keukenblok kamers | C6: Inventum Modesto Q10 (10 L, 2 kW) | D6: — | E6: Niet op BG-tekeningen; risico pantry's met water (€ 45.000, niet meegeprijsd).
A7: 3 | B7: Afvoer-sifoncombinatie keukenblok kamers | C7: McAlpine o.g. | D7: — | E7: Idem.
A8: 4 | B8: Douchepaneel douches | C8: De Melker MC.501229 M-Check | D8: E14 | E8: Prijs per douche verhoogd naar € 1.450 (compleet paneel).
A9: 5 | B9: Wastrog douches/wasruimte | C9: Intersan Sanilav 3.0 RVS 1200 mm | D9: E14 | E9: 4 wastroggen i.p.v. 8 wastafels (aanname: 2 tappunten per trog).
A10: 6 | B10: Afvoerput douches | C10: Aquaberg 4815 RVS | D10: E14 | E10: Opgenomen in douche-aansluiting (€ 1.600).
A11: 7 | B11: Douchebak 120x90 | C11: Wisa Wavedesign o.g. | D11: — | E11: BBN schrijft tegelvloer met afschot voor → niet meegeprijsd.
A12: 9 | B12: MIVA-WC | C12: Geberit 300 comfort verlengd + Duofix + Linido | D12: E14 | E12: MIVA-toiletruimte 0.72 (WC-02 op T.0.01).
A13: 10 | B13: MIVA-douche | C13: De Melker + Grohe Relexa + Linido douchezit | D13: — | E13: Geen MIVA-douche op BG-tekeningen.
A14: 11 | B14: MIVA-wastafel | C14: Geberit 300 comfort + Hansgrohe Care | D14: E14 | E14: MIVA-toiletruimte 0.72 (WT-02 op T.0.01).
A15: 12 | B15: Uitstortgootsteen | C15: Alape AG.Contra 505 + Daalderop | D15: — | E15: 3e verdieping; UG-01 op BG bestaand.
A16: 13 | B16: Centrale tapwateropstelling | C16: 2× Mitsubishi Q-Ton 30 kW + 3× Lapesa 1500 L | D16: — | E16: Bestaand, blijft gehandhaafd.
... A27: 24 | B27: Ruimtebedienapparaat fancoil | C27: CIAT RTR-E 7203 | D27: E13 | E27: Conflict met E&W (99DAsei) – prijs gelijk gehouden.

Sheet Tellingen
A1: Tellingen uit de tekeningen (versie 2)
A3: Onderdeel | B3: Aantal | C3: Tekening | D3: Toelichting | E3: Zekerheid
A4: Bewonerskamers | B4: 29 | C4: L.0.01-A/B, E.001 | D4: 17 in deel A (0.07–0.23), 12 in deel B (0.49–0.56, 0.50a, 0.74–0.76) | E4: Hoog
A5: Fancoils benodigd | B5: 34 | C5: L.0.01-A/B | D5: 1 per kamer (29) + 3 keuken 0.24 + 1 keuken 0.64 + 1 personeelsruimte 0.73 | E5: Middel
A6: Fancoils bestaand (demontage) | B6: 29 | C6: D.0.01-A/B | D6: 19 in deel A, 10 in deel B | E6: Middel
A7: Kanaalverwarmers/-koelers | B7: 6 | C7: E&W 7.1, L.0.01 | D7: 0.04, 0.05, 0.44, 0.45, 0.62, 0.63 | E7: Middel
A8: Brandkleppen | B8: ca. 64 | C8: L.0.01, E.001 | D8: 2 per kamer + ca. 6 in 60-min scheidingen | E8: Middel
A9: Roosters | B9: ca. 230 | C9: L.0.01-A/B | D9: 6 per kamer + keukens/overige ruimten | E9: Laag
A10: Douches | B10: 10 | C10: T.0.01 | D10: 4 in 0.42, 4 in 0.37, 2 in 0.70/0.71 | E10: Hoog
A11: Wastafels | B11: 8 | C11: T.0.01 | D11: 4 in 0.42, 4 in 0.37 | E11: Hoog
A12: Tappunten aanrecht | B12: 7 | C12: T.0.01 | D12: 3 in 0.24, 3 in 0.64, 1 pantry 0.01 | E12: Middel
A13: Wasmachines / drogers | B13: 4 / 3 | C13: T.0.01, E.001 | D13: wm/wd in 0.57 | E13: Hoog
A14: Water naar kamers (pantry) | B14: 0 | C14: T.0.01, R.0.01 | D14: Alleen koelkast (kk) per kamer | E14: Hoog
... A30: Douches in 0.37/0.42 | B30: 8 (waarvan 2 van 2,3 m²) | C30: Bijlage 1 | D30: 0.38–0.46; mogelijk 2 MIVA-douches (componentenboek nr. 10) | E30: Middel
